<sdf version="1.9">
<model name="floatingbase" canonical_link="base_link">
  <joint name="FreeFlyerRX" type="revolute">
    <pose relative_to="FreeFlyerZ_Link">0.00000 0.00000 0.00000 0.00000 0.00000 0.00000</pose>
    <parent>FreeFlyerZ_Link</parent>
    <child>FreeFlyerRX_Link</child>
    <axis>
      <limit>
        <lower>-1.57000</lower>
        <upper>1.57000</upper>
        <effort>0.00000</effort>
        <velocity>0.00000</velocity>
      </limit>
      <xyz>1.00000 0.00000 0.00000</xyz>
    </axis>
  </joint>
  <joint name="FreeFlyerRY" type="revolute">
    <pose relative_to="FreeFlyerRX_Link">0.00000 0.00000 0.00000 0.00000 0.00000 0.00000</pose>
    <parent>FreeFlyerRX_Link</parent>
    <child>FreeFlyerRY_Link</child>
    <axis>
      <limit>
        <lower>-1.57000</lower>
        <upper>1.57000</upper>
        <effort>0.00000</effort>
        <velocity>0.00000</velocity>
      </limit>
      <xyz>0.00000 1.00000 0.00000</xyz>
    </axis>
  </joint>
  <joint name="FreeFlyerRZ" type="revolute">
    <pose relative_to="FreeFlyerRY_Link">0.00000 0.00000 0.00000 0.00000 0.00000 0.00000</pose>
    <parent>FreeFlyerRY_Link</parent>
    <child>Body001_link</child>
    <axis>
      <limit>
        <lower>-1.57000</lower>
        <upper>1.57000</upper>
        <effort>0</effort>
        <velocity>0</velocity>
      </limit>
      <xyz>0.00000 0.00000 1.00000</xyz>
    </axis>
  </joint>
  <joint name="FreeFlyerX" type="prismatic">
    <pose relative_to="base_link">0.00000 0.00000 0.00000 0.00000 0.00000 0.00000</pose>
    <parent>base_link</parent>
    <child>FreeFlyerX_Link</child>
    <axis>
      <limit>
        <lower>-1.57000</lower>
        <upper>1.57000</upper>
        <effort>0.00000</effort>
        <velocity>0.00000</velocity>
      </limit>
      <xyz>1.00000 0.00000 0.00000</xyz>
    </axis>
  </joint>
  <joint name="FreeFlyerY" type="prismatic">
    <pose relative_to="FreeFlyerX_Link">0.00000 0.00000 0.00000 0.00000 0.00000 0.00000</pose>
    <parent>FreeFlyerX_Link</parent>
    <child>FreeFlyerY_Link</child>
    <axis>
      <limit>
        <lower>-1.57000</lower>
        <upper>1.57000</upper>
        <effort>0.00000</effort>
        <velocity>0.00000</velocity>
      </limit>
      <xyz>0.00000 1.00000 0.00000</xyz>
    </axis>
  </joint>
  <joint name="FreeFlyerZ" type="prismatic">
    <pose relative_to="FreeFlyerY_Link">0.00000 0.00000 0.00000 0.00000 0.00000 0.00000</pose>
    <parent>FreeFlyerY_Link</parent>
    <child>FreeFlyerZ_Link</child>
    <axis>
      <limit>
        <lower>-1.57000</lower>
        <upper>1.57000</upper>
        <effort>0.00000</effort>
        <velocity>0.00000</velocity>
      </limit>
      <xyz>0.00000 0.00000 1.00000</xyz>
    </axis>
  </joint>
  <joint name="SOLID001_link_joint" type="continuous">
    <pose relative_to="ZahnradGross004_link">-0.35193 -0.19263 0.42188 0.00000 0.00000 0.00000</pose>
    <parent>ZahnradGross004_link</parent>
    <child>SOLID001_link</child>
    <axis>
      <limit>
        <lower>0</lower>
        <upper>0</upper>
        <effort>0.00000</effort>
        <velocity>0.00000</velocity>
      </limit>
      <xyz>0.00000 0.00000 1.00000</xyz>
    </axis>
  </joint>
  <joint name="ZahnradGross003_link_joint" type="continuous">
    <pose relative_to="Body001_link">-0.00000 0.69593 0.55439 -1.57080 0.00000 0.00000</pose>
    <parent>Body001_link</parent>
    <child>ZahnradGross003_link</child>
    <axis>
      <limit>
        <lower>0</lower>
        <upper>0</upper>
        <effort>0.00000</effort>
        <velocity>0.00000</velocity>
      </limit>
      <xyz>0.00000 0.00000 1.00000</xyz>
    </axis>
  </joint>
  <joint name="ZahnradGross004_link_joint" type="continuous">
    <pose relative_to="ZahnradGross003_link">-0.35885 -0.17906 0.12975 0.00000 0.00000 0.00000</pose>
    <parent>ZahnradGross003_link</parent>
    <child>ZahnradGross004_link</child>
    <axis>
      <limit>
        <lower>0</lower>
        <upper>0</upper>
        <effort>0.00000</effort>
        <velocity>0.00000</velocity>
      </limit>
      <xyz>0.00000 0.00000 1.00000</xyz>
    </axis>
  </joint>
  <link name="Body001_link">
    <collision name="Base_collision">
      <pose relative_to="Body001_link">0.00000 0.00000 0.00000 0.00000 0.00000 0.00000</pose>
      <geometry>
        <mesh>
          <uri>../../../meshes/stl/Body.stl</uri>
          <scale>11.79544 11.79544 11.79544</scale>
        </mesh>
      </geometry>
      <surface>
        <contact/>
      </surface>
    </collision>
    <inertial>
      <inertia>
        <ixx>1.41731</ixx>
        <ixy>0.00042</ixy>
        <ixz>0.00026</ixz>
        <iyy>0.62211</iyy>
        <iyz>-0.12034</iyz>
        <izz>1.39114</izz>
      </inertia>
      <pose relative_to="Body001_link">0.00000 -0.14993 0.17821 0.00000 0.00000 0.00000</pose>
      <mass>10.00000</mass>
    </inertial>
    <visual name="Base">
      <material>
        <diffuse>0.30980 0.30196 0.80000 1.00000</diffuse>
        <specular>1.00000 1.00000 1.00000 0.49804</specular>
      </material>
      <pose relative_to="Body001_link">0.00000 0.00000 0.00000 0.00000 0.00000 0.00000</pose>
      <geometry>
        <mesh>
          <uri>../../../meshes/stl/Body.stl</uri>
          <scale>11.79544 11.79544 11.79544</scale>
        </mesh>
      </geometry>
    </visual>
  </link>
  <link name="FreeFlyerRX_Link"/>
  <link name="FreeFlyerRY_Link"/>
  <link name="FreeFlyerX_Link"/>
  <link name="FreeFlyerY_Link"/>
  <link name="FreeFlyerZ_Link"/>
  <link name="SOLID001_link">
    <collision name="SOLID001_collision">
      <pose relative_to="SOLID001_link">0.07336 -0.08760 0.19316 1.50960 1.57080 0.43890</pose>
      <geometry>
        <box>
          <size>1.18397 1.13183 0.09876</size>
        </box>
      </geometry>
      <surface>
        <contact/>
      </surface>
    </collision>
    <inertial>
      <inertia>
        <ixx>0.10421</ixx>
        <ixy>-0.00000</ixy>
        <ixz>0.00000</ixz>
        <iyy>0.09681</iyy>
        <iyz>0.00768</iyz>
        <izz>0.19068</izz>
      </inertia>
      <pose relative_to="SOLID001_link">0.05006 -0.08470 0.16790 0.00000 0.00000 0.00000</pose>
      <mass>1.00000</mass>
    </inertial>
    <visual name="SOLID001">
      <material>
        <diffuse>0.80000 0.80000 0.80000 1.00000</diffuse>
        <specular>1.00000 1.00000 1.00000 0.49804</specular>
      </material>
      <pose relative_to="SOLID001_link">0.03393 -0.06178 0.16789 1.07071 1.57080 0.00000</pose>
      <geometry>
        <mesh>
          <uri>../../../meshes/stl/SOLID.stl</uri>
          <scale>11.79544 11.79544 11.79544</scale>
        </mesh>
      </geometry>
    </visual>
  </link>
  <link name="ZahnradGross003_link">
    <collision name="ZahnradGross003_collision">
      <pose relative_to="ZahnradGross003_link">-0.00004 -0.00002 -0.02198 -3.14159 0.00000 -1.10796</pose>
      <geometry>
        <mesh>
          <uri>../../../meshes/stl/Cylinder.001.stl</uri>
          <scale>1.00474 1.00474 0.36513</scale>
        </mesh>
      </geometry>
      <surface>
        <contact/>
      </surface>
    </collision>
    <inertial>
      <inertia>
        <ixx>0.08436</ixx>
        <ixy>-0.00176</ixy>
        <ixz>-0.00000</ixz>
        <iyy>0.03283</iyy>
        <iyz>-0.00000</iyz>
        <izz>0.05282</izz>
      </inertia>
      <pose relative_to="ZahnradGross003_link">-0.02288 -0.01142 -0.02431 0.00000 0.00000 0.00000</pose>
      <mass>1.00000</mass>
    </inertial>
    <visual name="ZahnradGross003">
      <material>
        <diffuse>0.80000 0.80000 0.80000 1.00000</diffuse>
        <specular>1.00000 1.00000 1.00000 0.49804</specular>
      </material>
      <pose relative_to="ZahnradGross003_link">-0.00000 -0.00000 0.00000 -2.03363 1.57080 0.00000</pose>
      <geometry>
        <mesh>
          <uri>../../../meshes/stl/ZahnradGross.stl</uri>
          <scale>11.79544 11.79544 11.79544</scale>
        </mesh>
      </geometry>
    </visual>
  </link>
  <link name="ZahnradGross004_link">
    <collision name="ZahnradGross004_collision">
      <pose relative_to="ZahnradGross004_link">-0.00004 -0.00002 -0.02254 -3.14159 0.00000 -1.07071</pose>
      <geometry>
        <cylinder>
          <radius>0.45900</radius>
          <length>0.05712</length>
        </cylinder>
      </geometry>
      <surface>
        <contact/>
      </surface>
    </collision>
    <inertial>
      <inertia>
        <ixx>0.08436</ixx>
        <ixy>-0.00176</ixy>
        <ixz>-0.00000</ixz>
        <iyy>0.03283</iyy>
        <iyz>-0.00000</iyz>
        <izz>0.05282</izz>
      </inertia>
      <pose relative_to="ZahnradGross004_link">-0.02244 -0.01226 -0.02431 0.00000 0.00000 0.00000</pose>
      <mass>1.00000</mass>
    </inertial>
    <visual name="ZahnradGross004">
      <material>
        <diffuse>0.80000 0.80000 0.80000 1.00000</diffuse>
        <specular>1.00000 1.00000 1.00000 0.49804</specular>
      </material>
      <pose relative_to="ZahnradGross004_link">0.00000 0.00000 -0.00000 -0.14637 1.57080 1.92452</pose>
      <geometry>
        <mesh>
          <uri>../../../meshes/stl/ZahnradGross.001.stl</uri>
          <scale>11.79544 11.79545 11.79545</scale>
        </mesh>
      </geometry>
    </visual>
  </link>
  <link name="base_link">
    <inertial>
      <inertia>
        <ixx>0.00000</ixx>
        <ixy>0.00000</ixy>
        <ixz>0.00000</ixz>
        <iyy>0.00000</iyy>
        <iyz>0.00000</iyz>
        <izz>0.00000</izz>
      </inertia>
      <pose relative_to="base_link">0.00000 0.00000 0.00000 0.00000 0.00000 0.00000</pose>
      <mass>0.00000</mass>
    </inertial>
  </link>
  <plugin filename="gz-sim-joint-position-controller-system" name="gz::sim::systems::JointPositionController">
    <joint_name>SOLID001_link_joint</joint_name>
    <p_gain>20.00000</p_gain>
    <i_gain>0.00000</i_gain>
    <d_gain>0.00000</d_gain>
  </plugin>
  <plugin filename="gz-sim-joint-position-controller-system" name="gz::sim::systems::JointPositionController">
    <joint_name>ZahnradGross003_link_joint</joint_name>
    <p_gain>20.00000</p_gain>
    <i_gain>0.00000</i_gain>
    <d_gain>0.00000</d_gain>
  </plugin>
  <plugin filename="gz-sim-joint-position-controller-system" name="gz::sim::systems::JointPositionController">
    <joint_name>ZahnradGross004_link_joint</joint_name>
    <p_gain>20.00000</p_gain>
    <i_gain>0.00000</i_gain>
    <d_gain>0.00000</d_gain>
  </plugin>
</model>
</sdf>